Workbook

Sheet 填写说明 Instructions
B2: Autoliv 供应商可持续指数 · 填写说明
B3: Autoliv Supplier Sustainability Index (ASSI) — Instructions
B4: v1.0 (Cowork, 2026-08-01) · 共 133 题 / 6 大支柱 · 基准 Baseline：Polestar SSI 112 题
B6: 1. 用途：本 ASSI 用于 Autoliv 对直接材料供应商（备件采购、生产或服务）的新供应商准入评估，及现有供应商的年度可持续绩效评估。
B7: Purpose: The ASSI evaluates new suppliers under consideration and existing suppliers (annual assessment) for sourcing of parts, manufacturing or services.
B8: 2. 填写人：应由供应商有能力的人员（如可持续发展经理）完整填写；须同时提供集团与工厂两级信息。
B9: To be completed in full by competent personnel (e.g. sustainability manager); provide both corporate- and factory-level information.
B10: 3. 作答：在「问卷正文」表中，每题于『作答 Answer』列下拉选择 是 / 否 / 不适用(N/A)；并在『支持信息』列填写佐证，作为评分依据。
B11: Answering: for each question pick 是/否/N/A in the Answer column and fill Supporting Information as the basis for scoring.
B12: 4. 计分：总分与各支柱得分自动计算 —— 得分 = Σ权重(是) / Σ权重(全部，剔除 N/A) × 100。权重 1 或 3（透明度·冲突矿产·关键治理与安全项加权 3）。
B13: Scoring is automatic: score = Σweight(Yes) / Σweight(all, excl. N/A) × 100. Weights are 1 or 3.
B14: 5. 最低要求项（标记 R = Requirement）：不可谈判，作为长期合作最低门槛；任一 R 项答『否』即触发未达标提示，须优先整改。
... B33: Demo — 以 Polestar 提供测试问卷为基准重铸为 Autoliv 视角；融合 Autoliv《2025 Sustainable Sourcing Requirements》37 项与吉利/长城/长安/小米/蔚来/奇瑞等客户公开要求；客户名及供应商名按需脱敏，仅限与 Autoliv 沟通使用。

Sheet 工厂基本信息 General Info
B2: 工厂基本信息汇总 Factory Information Summary
B3: 『产品』指供货 Autoliv 的产品；『工厂』指生产该产品的工厂。黄色单元格为供应商填写项；右栏为示例格式。
B4: 字段 Field | C4: 填写 Fill in（黄色） | D4: 示例 Example format
B5: 基本信息 General
B6: 供应商代码 Supplier Code（如有） | D6: AEEK9
B7: 集团英文名称 Headquarter name (EN) | D7: (example) ACME Components AB
B8: 集团英文地址 Headquarter address (EN) | D8: Stockholm, Sweden
B9: 集团联系人 姓名/职务 Corporate contact / title | D9: Jane Doe / Sustainability Mgr
B10: 集团联系人 电话/邮箱 Corporate phone / email | D10: +46 … / jane@acme.com
B11: 工厂英文名称 Factory name (EN) | D11: ACME (Nanjing) Co., Ltd
B12: 工厂中文名称 Factory name (CN) | D12: 南京艾可密有限公司
B13: 工厂地址 Factory address | D13: Nanjing, Jiangsu, China
B14: 工厂联系人 姓名/职务 Factory contact / title | D14: Li Ming / SHE Manager
B15: 工厂联系人 电话/邮箱 Factory phone / email | D15: +86 … / li@acme.com
B16: 经营信息 Business
B17: 与 Autoliv 合作起始年 Year started with Autoliv | D17: 2019
B18: 供货 Autoliv 订单额（USD）Sales of Autoliv orders | D18: 2.2M
B19: 供货 Autoliv 的产品 Product(s) to Autoliv | D19: Seat belt webbing
B20: 供货车型 / 零件号 Models / part numbers | D20: P514 / 12345-AB
B21: 企业性质 Enterprise type（国营/民企/外资） | D21: Foreign / 外资
B22: 其他主要客户 Other major customers | D22: …
B23: 人事工资 HR & Pay
B24: 员工总数（含派遣）Total employees (incl. agency) | D24: 1309
B25: 女员工比例 Female % | D25: 53.6%
B26: 未成年工总数 Juvenile workers | D26: 0
B27: 生产一线班次与工时 Shifts / hours | D27: 2 shift / 5 days
B28: 当地法定最低工资 Local minimum wage | D28: 2280 CNY
B29: 生产与能源 Production & Energy
B30: 生产工序 Manufacturing process | D30: Assembly
B31: 月产能 / 年产量 Monthly capacity / annual output | D31: 5,000,000 / 52,850,000
B32: 外购电量（kWh）Electricity purchased | D32: 6,500,000
B33: 自发可再生电量（kWh）Onsite renewable elec. | D33: 0
B34: 外购绿电量（kWh）Purchased renewable elec. | D34: 0
B35: 煤/天然气/燃料油/蒸汽/压缩空气 消耗量 Other energy | D35: 0 / 0 / 0 / 0 / 0
B36: 其他信息 Other
B37: 客户 CSR/环境/能源审核记录 Client audits（客户名·年份·产线） | D37: SGS ISO14001 ext. audit 2022
B38: 供货 Autoliv 产品主要原材料供应商 Tier 1–4（名称·地址） | D38: …

Sheet 问卷正文 Questionnaire
A1: Autoliv 供应商可持续指数 · 问卷正文 | ASSI Questionnaire | E1: 当前总分 Score → | F1: =IF(SUM(O6:O138)=0,"",ROUND(SUM(P6:P138)/SUM(O6:O138)*100,1)) -> 0
A2: 作答方式：在『作答 Answer』列下拉选择 是/否/不适用；黄色单元格为供应商填写项。总分与各支柱得分自动计算（详见『计分汇总』表）。
A3: Pick 是/否/不适用 in the Answer column; yellow cells are for the supplier. Score auto-updates — see the Score sheet.
A4: 编号 No. | B4: 支柱 Pillar | C4: 二级目录 Subcategory | D4: 对象 Subject | E4: 题目（中文） Question (CN) | F4: Question (EN) | G4: 说明与证据要求 Guideline / Evidence | H4: 作答 Answer | I4: 支持信息 Supporting Info | J4: 行动计划 Action Plan | K4: 强制 R/E/N | L4: 权重 Wt | M4: 对齐#37 Align | N4: 来源 Source | O4: 分母 denom | P4: 分子 num
A5: 示例 | B5: — 示例行 EXAMPLE — | C5: (示例) | D5: 工厂 Fac | E5: （此行为示例，请勿填写；正式题目从下一行开始） | F5: (Example row — do not fill in; real questions start below) | G5: 如『是』请在支持信息栏提供佐证。 | H5: 是 | I5: 例：已通过 ISO 14064 组织碳盘查，报告见附件。 | J5: 例：2026Q4 前完成第三方核查。 | K5: R | L5: 1 | M5: #8 | N5: 示例 Example | O5: =IF(H5="不适用",0,L5) -> 1 | P5: =IF(H5="是",L5,0) -> 1
A6: 1 | B6: P1 可持续管理框架与传导 | C6: 治理责任 Governance | D6: 集团 | E6: 公司是否任命高管层的可持续发展负责人（涵盖社会/合规/环境），职责已成文并保持联系方式更新？ | F6: Has the company appointed an executive-level sustainability lead (covering social, compliance and environment), with documented responsibilities and up-to-date contact details? | G6: 如果'是'，请提供负责人姓名/职务/联系方式。 / If "Yes", provide the lead's name/title/contact. | K6: R | L6: 1 | M6: #33 高管可持续责任人 | N6: Autoliv 采购要求 #33 | O6: =IF(H6="不适用",0,L6) -> 1 | P6: =IF(H6="是",L6,0) -> 0
A7: 2 | B7: P1 可持续管理框架与传导 | C7: 采购及供应商管理 | D7: 集团+工厂 | E7: 选择供应商时，是否将低碳与可持续要求（含 Autoliv 采购要求）作为准入与选择标准？ | F7: When selecting suppliers, do you apply low-carbon and sustainability requirements (including Autoliv's sourcing requirements) as qualification/selection criteria? | G7: 如果'是'，请在支持信息栏说明具体准入标准。可将 Autoliv 低碳准入标准固化进您的供应商准入流程。 / If "Yes", specify the qualification criteria; Autoliv's low-carbon criteria can be embedded into your supplier onboarding. | K7: 计分 | L7: 1 | M7: #34 向上游传导 / #36 年度自评 | N7: Polestar SSI（基准） | O7: =IF(H7="不适用",0,L7) -> 1 | P7: =IF(H7="是",L7,0) -> 0
A8: 3 | B8: P1 可持续管理框架与传导 | C8: 要求传导 Cascade | D8: 集团+工厂 | E8: 是否已将 Autoliv 全部可持续采购要求逐条传导至上游（Tier-2），并验证 Tier-2 已采纳、要求其继续向 Tier-3 传导？ | F8: Have you cascaded ALL of Autoliv's sustainability sourcing requirements to your upstream (Tier-2), verified Tier-2 adoption, and required onward cascade to Tier-3? | G8: 如果'是'，请说明传导方式（合同/问卷/平台）、已覆盖 Tier-2 家数与回执验证方式。此为链主传导关键项。 / If "Yes", describe the cascade method, number of Tier-2 covered, and receipt-verification. Keystone of chain-lead cascade. | K8: R | L8: 3 | M8: #34 向上游传导并验证 | N8: Autoliv 采购要求 #34 · 吉利/奇瑞（要求核心供应商向上传导） | O8: =IF(H8="不适用",0,L8) -> 3 | P8: =IF(H8="是",L8,0) -> 0
A9: 4 | B9: P1 可持续管理框架与传导 | C9: 采购及供应商管理 | D9: 集团+工厂 | E9: 是否对上游供应商开展环保与减排培训？（培训记录即作为支持信息） | F9: Do you provide environmental-protection and emission-reduction training to upstream suppliers? (training records serve as supporting information) | G9: 如果'是'，请提供最近一次培训的时间、地点、参与供应商数量。Autoliv 平台可提供减排/LCA/SBTi 培训课程。 / If "Yes", provide date/location/number of participating suppliers of the last session. | K9: 计分 | L9: 1 | M9: #34 向上游传导 / #36 年度自评 | N9: Polestar SSI（基准） | O9: =IF(H9="不适用",0,L9) -> 1 | P9: =IF(H9="是",L9,0) -> 0
A10: 5 | B10: P1 可持续管理框架与传导 | C10: 全链溯源 Traceability | D10: 工厂 | E10: 是否能按 Autoliv 零件号将供应链追溯至 Tier-N（含原材料级），并全力配合 Autoliv 信息请求？ | F10: Can you trace the supply chain by Autoliv part number down to Tier-N (incl. raw-material level) and fully support Autoliv information requests? | G10: 期望项（2025）。如'是'，说明溯源系统与覆盖层级。 / Expectation (2025). If "Yes", describe the traceability system and coverage. | K10: E | L10: 1 | M10: #35 按零件号全链溯源 | N10: Autoliv 采购要求 #35 · 吉利（GeeTrace 溯源） | O10: =IF(H10="不适用",0,L10) -> 1 | P10: =IF(H10="是",L10,0) -> 0
A11: 6 | B11: P1 可持续管理框架与传导 | C11: 采购及供应商管理 | D11: 集团+工厂 | E11: 是否建立对上游供应商定期环境（及可持续）考核机制，并要求考核结果较差的供应商限期改善？ | F11: Do you operate a mechanism for regular environmental (and sustainability) assessment of upstream suppliers, requiring underperformers to improve within a deadline? | G11: 如果'是'，请说明考核频率、指标与末位改善流程。对齐 Autoliv #34 传导与验证。 / If "Yes", describe frequency, metrics and the underperformer-improvement process. | K11: 计分 | L11: 1 | M11: #34 向上游传导 / 供应商考核 | N11: Polestar SSI（基准） | O11: =IF(H11="不适用",0,L11) -> 1 | P11: =IF(H11="是",L11,0) -> 0
A12: 7 | B12: P1 可持续管理框架与传导 | C12: 年度自评 Self-assessment | D12: 集团 | E12: 是否承诺按 Autoliv 要求 100% 完整完成年度供应商可持续自评问卷（本问卷 / SupplierAssurance-NQC 平台）？ | F12: Do you commit to completing Autoliv's annual supplier sustainability self-assessment (this form / SupplierAssurance-NQC platform) at 100% response? | G12: Requirement（2023）。工具衔接 NQC / Drive Sustainability SAQ 5.0。 / Requirement (2023). Tool links to NQC / Drive Sustainability SAQ 5.0. | K12: R | L12: 1 | M12: #36 年度自评（100% 响应） | N12: Autoliv 采购要求 #36 · Drive Sustainability SAQ 5.0 | O12: =IF(H12="不适用",0,L12) -> 1 | P12: =IF(H12="是",L12,0) -> 0
A13: 8 | B13: P1 可持续管理框架与传导 | C13: 现场审核 Audit | D13: 工厂 | E13: 是否接受并全力配合 Autoliv 及其授权第三方的现场审核，并对发现项制定与落实纠正措施（每 3 年或按风险提前）？ | F13: Do you accept and fully support on-site audits by Autoliv or its authorized third party, and define/implement corrective actions (every 3 years or earlier by risk)? | G13: Requirement（2023）。 / Requirement (2023). | K13: R | L13: 3 | M13: #37 配合 Autoliv 现场审核 | N13: Autoliv 采购要求 #37 · 蔚来(2025年96次现场评审)· 小米(611家现场审核)· RSCI 11 模块 | O13: =IF(H13="不适用",0,L13) -> 3 | P13: =IF(H13="是",L13,0) -> 0
A14: 9 | B14: P2 气候中和 | C14: 管理战略 | D14: 集团+工厂 | E14: 是否在工厂发展战略规划、发展理念等管理方针文件中，包含节能减排等相关内容？ | F14: Are energy conservation and GHG-emission reduction included in the factory's development strategy planning, development concept and other management policies? | G14: If “Yes", please specify in column L. / 如果‘是’，请在L栏描述相关内容。 | K14: 计分 | L14: 1 | M14: #8 全范围GHG追踪 / #7 减排目标 | N14: Polestar SSI（基准） | O14: =IF(H14="不适用",0,L14) -> 1 | P14: =IF(H14="是",L14,0) -> 0
A15: 10 | B15: P2 气候中和 | C15: 管理战略 | D15: 集团+工厂 | E15: 是否有（1）能耗数据统计和（2）碳排放计算和管理？ | F15: Are there: (1) energy consumption data; (2) GHG-emission calculation and management? | G15: If “Yes", please describe the methods of energy consumption and carbon emission calculations in column L. / 如果‘是’，请在L栏描述如何进行能耗数据统计和碳排放计算。 | K15: R | L15: 1 | M15: #8 全范围GHG追踪 / #7 减排目标 | N15: Polestar SSI（基准） | O15: =IF(H15="不适用",0,L15) -> 1 | P15: =IF(H15="是",L15,0) -> 0
A16: 11 | B16: P2 气候中和 | C16: 管理战略 | D16: 集团+工厂 | E16: 是否知道碳减排的概念和知识，是否已经或正在制定碳减排的方案？ | F16: Are you familiar with the concept and knowledge of GHG-emission reduction? Is there a GHG-emission reduction scheme developed or under development? | K16: R | L16: 1 | M16: #8 全范围GHG追踪 / #7 减排目标 | N16: Polestar SSI（基准） | O16: =IF(H16="不适用",0,L16) -> 1 | P16: =IF(H16="是",L16,0) -> 0
A17: 12 | B17: P2 气候中和 | C17: 管理战略 | D17: 集团+工厂 | E17: 是否有负责碳排放统计和管理人员？ | F17: Is there personnel responsible for GHG-emission data and management? | G17: If “Yes", please provide the name and title in column L. / 如果‘是’，请在L栏描述姓名和职位。 | K17: R | L17: 1 | M17: #8 全范围GHG追踪 / #7 减排目标 | N17: Polestar SSI（基准） | O17: =IF(H17="不适用",0,L17) -> 1 | P17: =IF(H17="是",L17,0) -> 0
A18: 13 | B18: P2 气候中和 | C18: 管理战略 | D18: 集团+工厂 | E18: 是否设立何时达到碳中和目标？ | F18: Is there a target for when to achieve net-zero GHG-emissions? | K18: 计分 | L18: 1 | M18: #8 全范围GHG追踪 / #7 减排目标 | N18: Polestar SSI（基准） | O18: =IF(H18="不适用",0,L18) -> 1 | P18: =IF(H18="是",L18,0) -> 0
A19: 14 | B19: P2 气候中和 | C19: 管理战略 Management Strategy | D19: 集团 | E19: 减排目标是否已经或计划经科学碳目标倡议（SBTi）批准（2028 年前完成；战略供应商可能被提前要求）？ | F19: Are your emission-reduction targets approved (or planned) by the Science Based Targets initiative (SBTi), to be completed before 2028? | G19: Expectation（2028）。平台提供 SBTi 辅导课程。 / Expectation (2028). Platform offers SBTi coaching. | K19: E | L19: 1 | M19: #5 SBTi 认证目标 | N19: Autoliv 采购要求 #5 · 吉利/蔚来（已承诺 SBTi） | O19: =IF(H19="不适用",0,L19) -> 1 | P19: =IF(H19="是",L19,0) -> 0
A20: 15 | B20: P2 气候中和 | C20: 管理战略 Management Strategy | D20: 集团 | E20: 是否承诺供货 Autoliv 产品的全供应链 2040 年净零排放，且较 2018 基年 2030 年绝对减排（范围一二三）≥30%？ | F20: Have you committed to net-zero across the full supply chain (for products supplied to Autoliv) by 2040, and ≥30% absolute reduction (Scope 1/2/3) by 2030 vs 2018 baseline? | G20: Expectation（#6/#7）。 / Expectation (#6/#7). | K20: E | L20: 1 | M20: #6 供应链净零 2040 / #7 2030 绝对减排 ≥30% | N20: Autoliv 采购要求 #6/#7 · OEM 净零(吉利/长城2045·长安2045峰值2027·奇瑞2047·小米2040运营) | O20: =IF(H20="不适用",0,L20) -> 1 | P20: =IF(H20="是",L20,0) -> 0
A21: 16 | B21: P2 气候中和 | C21: 采购及供应商管理 | D21: 工厂 | E21: 是否要求上游供应商提供碳排放数据？ | F21: Do you request GHG-emission data from upstream suppliers? | K21: 计分 | L21: 1 | M21: #8 全范围GHG追踪（上游） | N21: Polestar SSI（基准） | O21: =IF(H21="不适用",0,L21) -> 1 | P21: =IF(H21="是",L21,0) -> 0
A22: 17 | B22: P2 气候中和 | C22: 设计 | D22: 工厂 | E22: 是否在产品设计中用环境影响较小的替代品来替代对环境较大影响的资源？ | F22: Do you substitute resources that have adverse environmental impacts with less impactful substitutes in your product design? | G22: If “Yes", please provide examples in column L. / 如果‘是’，请在L栏举例说明。 | K22: 计分 | L22: 1 | M22: #2 LCA | N22: Polestar SSI（基准） | O22: =IF(H22="不适用",0,L22) -> 1 | P22: =IF(H22="是",L22,0) -> 0
A23: 18 | B23: P2 气候中和 | C23: 生产-温室气体核算和申报 | D23: 工厂 | E23: 是否对所有主要温室气体（CO2, CH4, N2O, HFCs, PFCs, SF6）进行核算? | F23: Have you conducted accounting on all major greenhouse gases (GHGs) (CO2, CH4, N2O, HFCs, PFCs, SF6)? | G23: If “Yes", please provide in column L: (1) names of GHGs accounted; (2) standards adopted for accounting. / 如果‘是’，请L栏描述(1)核算何种温室气体(2)核算所采用的标准名称 | K23: 计分 | L23: 1 | M23: #8 全范围GHG追踪 | N23: Polestar SSI（基准） | O23: =IF(H23="不适用",0,L23) -> 1 | P23: =IF(H23="是",L23,0) -> 0
A24: 19 | B24: P2 气候中和 | C24: 生产-温室气体核算和申报 | D24: 工厂 | E24: 是否采用国际标准/国家标准对scope 1（至少一种温室气体）进行核算？ | F24: Have you calculated scope 1 GHG-emission in line with international/national standards? | G24: If “Yes", please provide in column L: (1) emission in ton CO2e; (2) standards adopted for accounting; (3) emission per unit of production value. / GHG emission per unit of production value can be calculated as: C=A/B, where: / C--GHG emission per unit of production value, in tonCO2e/10000CNY; / A--Calculated scope 2 GHG emissions, in ton CO2e; / B--Production value of the corporate last year, in 10000 CNY | K24: R | L24: 1 | M24: #8 全范围GHG追踪 | N24: Polestar SSI（基准） | O24: =IF(H24="不适用",0,L24) -> 1 | P24: =IF(H24="是",L24,0) -> 0
A25: 20 | B25: P2 气候中和 | C25: 生产-温室气体核算和申报 | D25: 工厂 | E25: 是否采用国际标准/国家标准对scope 2（至少一种温室气体）进行核算？ | F25: Have you calculated scope 2 GHG-emission in line with international/national standards? | G25: If “Yes", please provide in column L: (1) emission in ton CO2e; (2) standards adopted for accounting; (3) emission per unit of production value. / GHG emission per unit of production value can be calculated as: C=A/B, where: / C--GHG emission per unit of production value, in tonCO2e/10000CNY; / A--Calculated scope 2 GHG emissions, in ton CO2e; / B--Production value of the corporate last year, in 10000 CNY | K25: R | L25: 1 | M25: #8 全范围GHG追踪 | N25: Polestar SSI（基准） | O25: =IF(H25="不适用",0,L25) -> 1 | P25: =IF(H25="是",L25,0) -> 0
A26: 21 | B26: P2 气候中和 | C26: 生产-温室气体核算和申报 | D26: 工厂 | E26: 是否采用国际标准/国家标准对Scope 3的温室气体（至少一种温室气体）进行核算？ | F26: Have you calculated scope 3 GHG-emission in line with international/national standards? | G26: If “Yes", please provide in column L: (1) emission in ton CO2e; (2) standards adopted for accounting. / Scope 3 refers to all indirect emissions other than scope 2 that occur in the company's value chain, which are generated in related to the company's business but the emission sources are not owned or controlled by the company. / 如果‘是’，请在L栏描述：(1)排放量（单位ton CO2e）；(2)核算所采用的标准名称 / Scope3是指所有不属于Scope2的间接排放， | K26: 计分 | L26: 1 | M26: #8 全范围GHG追踪 | N26: Polestar SSI（基准） | O26: =IF(H26="不适用",0,L26) -> 1 | P26: =IF(H26="是",L26,0) -> 0
A27: 22 | B27: P2 气候中和 | C27: 生产-温室气体核算和申报 | D27: 工厂 | E27: 是否采用适用标准（如 ISO 14067）对交付 Autoliv 的产品进行产品碳足迹（PCF）核算或核查？ | F27: Have you accounted/verified the Product Carbon Footprint (PCF) of products supplied to Autoliv using applicable standards (e.g. ISO 14067)? | G27: 如果'是'，请提供：(1) 排放量（tCO2e 或 kgCO2e，标明单位）；(2) 采用标准。与 Autoliv 新要求 #3 衔接。 / If "Yes", provide emission with unit and the standard adopted. Links to Autoliv new requirement #3. | K27: 计分 | L27: 1 | M27: #3 产品碳足迹 PCF | N27: Polestar SSI（基准） | O27: =IF(H27="不适用",0,L27) -> 1 | P27: =IF(H27="是",L27,0) -> 0
A28: 23 | B28: P2 气候中和 | C28: 生产-温室气体核算和申报 GHG Accounting | D28: 工厂 | E28: 是否能按 ISO 14067 + GHG Protocol + Catena-X Carbon Rulebook 核算交付 Autoliv 产品的"从摇篮到 Autoliv 大门"产品碳足迹（PCF），并支持 ALV GHG 申报 / CBAM / IMDS 报送？ | F28: Can you calculate the cradle-to-Autoliv-gate Product Carbon Footprint (PCF) per ISO 14067 + GHG Protocol + Catena-X Carbon Rulebook, supporting ALV GHG declaration / CBAM / IMDS reporting? | G28: 新要求 New Requirement（2025）。 / New Requirement (2025). | K28: N | L28: 3 | M28: #3 产品碳足迹 PCF（新要求） | N28: Autoliv 采购要求 #3 | O28: =IF(H28="不适用",0,L28) -> 3 | P28: =IF(H28="是",L28,0) -> 0
A29: 24 | B29: P2 气候中和 | C29: 生产-温室气体核算和申报 | D29: 工厂 | E29: 以上温室气体核算是否有第三方认证？ | F29: Is there third party certification for the above GHG-accounting? | G29: If “Yes", please provide in column L: (1) name of certificate; (2) scope; (3) certifying party. / 如果‘是’，请在L栏描述：(1)证书名称；(2)涉及的温室气体审核范围；(3)颁发机构 | K29: 计分 | L29: 1 | M29: #8 GHG追踪 / 披露 | N29: Polestar SSI（基准） | O29: =IF(H29="不适用",0,L29) -> 1 | P29: =IF(H29="是",L29,0) -> 0
A30: 25 | B30: P2 气候中和 | C30: 生产-温室气体核算和申报 | D30: 工厂 | E30: 对供应链的温室气体设置过减排目标？ | F30: Have you set targets for reducing GHG-emissions in your supply chain? | G30: If “Yes", please describe the targets in column L. / 如果‘是’，请L栏描述供应链减排目标。 | K30: 计分 | L30: 1 | M30: #8 GHG追踪 / 披露 | N30: Polestar SSI（基准） | O30: =IF(H30="不适用",0,L30) -> 1 | P30: =IF(H30="是",L30,0) -> 0
A31: 26 | B31: P2 气候中和 | C31: 生产-温室气体核算和申报 | D31: 工厂 | E31: 是否在CDP/政府网站等公共平台上公开温室气体排放数据？ | F31: Are your GHG-emission data available on public platforms such as CDP/ government websites? | G31: If “Yes", please provide the website links in column L. / 如果‘是’，请在L栏提供相关网站链接。 | K31: 计分 | L31: 1 | M31: #8 GHG追踪 / 披露 | N31: Polestar SSI（基准） | O31: =IF(H31="不适用",0,L31) -> 1 | P31: =IF(H31="是",L31,0) -> 0
A32: 27 | B32: P2 气候中和 | C32: 生产-可再生能源使用 Renewable Energy | D32: 工厂 | E32: 申报的绿电比例是否有合规凭证支持（EAC/REC/I-REC/GO 或 PPA，当年退役、注明电量与来源）？注：电网平均绿电占比与核电不计入。 | F32: Is your declared renewable-electricity share backed by compliant certificates (EAC/REC/I-REC/GO or PPA, retired in-year, stating volume & origin)? Grid-average renewable share and nuclear do NOT count. | G32: Requirement（2023）。平台提供绿电绿证管理。 / Requirement (2023). Platform offers green-power / REC management. | K32: R | L32: 1 | M32: #16 绿电比例申报（凭证合规） | N32: Autoliv 采购要求 #16 | O32: =IF(H32="不适用",0,L32) -> 1 | P32: =IF(H32="是",L32,0) -> 0
A33: 28 | B33: P2 气候中和 | C33: 生产-可再生能源使用 Renewable Energy | D33: 集团+工厂 | E33: 是否已承诺 Autoliv 绿电路线图——自身用电 2025 年 ≥30%、2027 年 ≥60%、2030 年 100%，并要求上游 Tier-N 同步承诺？ | F33: Have you committed to Autoliv's green-power trajectory — ≥30% by 2025, ≥60% by 2027, 100% by 2030 — and required Tier-N upstream to commit likewise? | G33: Expectation（#17-19）。 / Expectation (#17-19). | K33: E | L33: 1 | M33: #17–#20 绿电路线图 | N33: Autoliv 采购要求 #17-20 · 奇瑞(核心T1 2030绿电≥60%)· 吉利(2025 100%)· 小米(链T1 2025目标50%+) | O33: =IF(H33="不适用",0,L33) -> 1 | P33: =IF(H33="是",L33,0) -> 0
... A44: 39 | B44: P2 气候中和 | C44: 生产-节能措施 | D44: 工厂 | E44: 近一年内是否有节能改造项目并达到预期效果? | F44: Have you carried out energy efficiency retrofit projects in the past year and achieved the expected results? | G44: If “Yes", please describe the implemented energy efficiency retrofit projects. / 如果‘是’，请在L栏描述已实施的节能改造项目。 | K44: 计分 | L44: 1 | M44: #8 能源管理 / 节能 | N44: Polestar SSI（基准） | O44: =IF(H44="不适用",0,L44) -> 1 | P44: =IF(H44="是",L44,0) -> 0
A45: 40 | B45: P2 气候中和 | C45: 生产-节能措施 | D45: 工厂 | E45: 是否设置在线能源计量管理系统？ | F45: Have you installed online energy metering management system? | K45: 计分 | L45: 1 | M45: #8 能源管理 / 节能 | N45: Polestar SSI（基准） | O45: =IF(H45="不适用",0,L45) -> 1 | P45: =IF(H45="是",L45,0) -> 0
A46: 41 | B46: P2 气候中和 | C46: 生产-节能措施 | D46: 工厂 | E46: 是否使用LED等节能型照明设备，且用占比不低于50%？ | F46: Do you use energy-saving lightings such as LEDs, and the proportion is not less than 50%? | K46: 计分 | L46: 1 | M46: #8 能源管理 / 节能 | N46: Polestar SSI（基准） | O46: =IF(H46="不适用",0,L46) -> 1 | P46: =IF(H46="是",L46,0) -> 0
A47: 42 | B47: P2 气候中和 | C47: 生产-节能措施 | D47: 工厂 | E47: 是否建有厂区清洁能源电站（生物质，太阳能，风能等）？ | F47: Do you have any on-site renewable energy sources (biomass, solar, wind)? | G47: Please state estimated % of on-site renewable thermal energy and/or electricity sources consumption? / 请描述厂区内清洁能源类型和占比 | K47: 计分 | L47: 1 | M47: #8 能源管理 / 节能 | N47: Polestar SSI（基准） | O47: =IF(H47="不适用",0,L47) -> 1 | P47: =IF(H47="是",L47,0) -> 0
A48: 43 | B48: P2 气候中和 | C48: 分材料减排路线图 Material Roadmaps | D48: 工厂 | E48: 是否为供货 Autoliv 的主要金属材料制定减排/再生路线图——钢材 GHG 较 2018 降 ≥35%（2030）、再生铝 ≥75%（或 <4kg CO2e/kg）、再生镁 ≥40%（或 <10kg CO2e/kg），并在 IMDS 记录再生比例？ | F48: Have you set decarbonization/recycled-content roadmaps for the main metals supplied to Autoliv — steel GHG −35% vs 2018 by 2030, recycled aluminium ≥75% (or <4kg CO2e/kg), recycled magnesium ≥40% (or <10kg CO2e/kg) — recording recycled share in IMDS? | G48: Expectation（#9-11）。含气体发生器金属壳体。 / Expectation (#9-11). Incl. inflator metal housings. | K48: E | L48: 1 | M48: #9 钢 / #10 铝 / #11 镁 减排路线图 | N48: Autoliv 采购要求 #9-11 · 吉利(再生钢20%/铝30%)· 奇瑞(100%再生铝一体压铸) | O48: =IF(H48="不适用",0,L48) -> 1 | P48: =IF(H48="是",L48,0) -> 0
A49: 44 | B49: P2 气候中和 | C49: 分材料减排路线图 Material Roadmaps | D49: 工厂 | E49: 是否为树脂与织物类材料制定减排路线图（GHG 较 2018 降 ≥35%，2030），并在 IMDS 记录再生比例？ | F49: Have you set decarbonization roadmaps for resins and fabrics (GHG −35% vs 2018 by 2030) and recorded recycled share in IMDS? | G49: Expectation（#12-13）。 / Expectation (#12-13). | K49: E | L49: 1 | M49: #12 树脂 / #13 织物 减排路线图 | N49: Autoliv 采购要求 #12-13 · 吉利(再生塑料25%) | O49: =IF(H49="不适用",0,L49) -> 1 | P49: =IF(H49="是",L49,0) -> 0
A50: 45 | B50: P2 气候中和 | C50: 物流 | D50: 工厂 | E50: 是否开展绿色物流研究，制定原材料、零部件、场内物料、汽车产品等高效运输方案，提升能源效率、降低污染物排放？ | F50: Have you carried out research on green logistics and formulate efficient transportation plans for raw materials, parts, on-site materials, and automotive products to improve energy efficiency and reduce pollutant emissions? | K50: 计分 | L50: 1 | M50: #14 运输减排路线图 | N50: Polestar SSI（基准） | O50: =IF(H50="不适用",0,L50) -> 1 | P50: =IF(H50="是",L50,0) -> 0
...

Sheet 计分汇总 Score
B2: 计分汇总 Score Summary
B3: 得分 = Σ权重(是) / Σ权重(全部，剔除 N/A) × 100；数据来源『问卷正文』。作答后自动刷新。
B5: 支柱 Pillar | C5: 题数 Q | D5: 当前得分 Score | E5: 满分 Wt | F5: 最低项 R | G5: R 未达标 Below-min
B6: P1 可持续管理框架与传导 | C6: =COUNTIF('问卷正文 Questionnaire'!$B$6:$B$138,B6&"*") -> 8 | D6: =IF(SUMIFS('问卷正文 Questionnaire'!$O$6:$O$138,'问卷正文 Questionnaire'!$B$6:$B$138,B6&"*")=0,"—",ROUND(SUMIFS('问卷正文 Questionnaire'!$P$6:$P$138,'问卷正文 Questionnaire'!$B$6:$B$138,B6&"*")/SUMIFS('问卷正文 Questionnaire'!$O$6:$O$138,'问卷正文 Questionnaire'!$B$6:$B$138,B6&"*")*100,1)) -> 0 | E6: =SUMIFS('问卷正文 Questionnaire'!$O$6:$O$138,'问卷正文 Questionnaire'!$B$6:$B$138,B6&"*") -> 12 | F6: =COUNTIFS('问卷正文 Questionnaire'!$B$6:$B$138,B6&"*",'问卷正文 Questionnaire'!$K$6:$K$138,"R") -> 4 | G6: =COUNTIFS('问卷正文 Questionnaire'!$B$6:$B$138,B6&"*",'问卷正文 Questionnaire'!$K$6:$K$138,"R",'问卷正文 Questionnaire'!$H$6:$H$138,"否") -> 0
B7: P2 气候中和 | C7: =COUNTIF('问卷正文 Questionnaire'!$B$6:$B$138,B7&"*") -> 38 | D7: =IF(SUMIFS('问卷正文 Questionnaire'!$O$6:$O$138,'问卷正文 Questionnaire'!$B$6:$B$138,B7&"*")=0,"—",ROUND(SUMIFS('问卷正文 Questionnaire'!$P$6:$P$138,'问卷正文 Questionnaire'!$B$6:$B$138,B7&"*")/SUMIFS('问卷正文 Questionnaire'!$O$6:$O$138,'问卷正文 Questionnaire'!$B$6:$B$138,B7&"*")*100,1)) -> 0 | E7: =SUMIFS('问卷正文 Questionnaire'!$O$6:$O$138,'问卷正文 Questionnaire'!$B$6:$B$138,B7&"*") -> 40 | F7: =COUNTIFS('问卷正文 Questionnaire'!$B$6:$B$138,B7&"*",'问卷正文 Questionnaire'!$K$6:$K$138,"R") -> 6 | G7: =COUNTIFS('问卷正文 Questionnaire'!$B$6:$B$138,B7&"*",'问卷正文 Questionnaire'!$K$6:$K$138,"R",'问卷正文 Questionnaire'!$H$6:$H$138,"否") -> 0
B8: P3 循环性 | C8: =COUNTIF('问卷正文 Questionnaire'!$B$6:$B$138,B8&"*") -> 29 | D8: =IF(SUMIFS('问卷正文 Questionnaire'!$O$6:$O$138,'问卷正文 Questionnaire'!$B$6:$B$138,B8&"*")=0,"—",ROUND(SUMIFS('问卷正文 Questionnaire'!$P$6:$P$138,'问卷正文 Questionnaire'!$B$6:$B$138,B8&"*")/SUMIFS('问卷正文 Questionnaire'!$O$6:$O$138,'问卷正文 Questionnaire'!$B$6:$B$138,B8&"*")*100,1)) -> 0 | E8: =SUMIFS('问卷正文 Questionnaire'!$O$6:$O$138,'问卷正文 Questionnaire'!$B$6:$B$138,B8&"*") -> 29 | F8: =COUNTIFS('问卷正文 Questionnaire'!$B$6:$B$138,B8&"*",'问卷正文 Questionnaire'!$K$6:$K$138,"R") -> 1 | G8: =COUNTIFS('问卷正文 Questionnaire'!$B$6:$B$138,B8&"*",'问卷正文 Questionnaire'!$K$6:$K$138,"R",'问卷正文 Questionnaire'!$H$6:$H$138,"否") -> 0
B9: P4 负责任商业与透明度 | C9: =COUNTIF('问卷正文 Questionnaire'!$B$6:$B$138,B9&"*") -> 17 | D9: =IF(SUMIFS('问卷正文 Questionnaire'!$O$6:$O$138,'问卷正文 Questionnaire'!$B$6:$B$138,B9&"*")=0,"—",ROUND(SUMIFS('问卷正文 Questionnaire'!$P$6:$P$138,'问卷正文 Questionnaire'!$B$6:$B$138,B9&"*")/SUMIFS('问卷正文 Questionnaire'!$O$6:$O$138,'问卷正文 Questionnaire'!$B$6:$B$138,B9&"*")*100,1)) -> 0 | E9: =SUMIFS('问卷正文 Questionnaire'!$O$6:$O$138,'问卷正文 Questionnaire'!$B$6:$B$138,B9&"*") -> 47 | F9: =COUNTIFS('问卷正文 Questionnaire'!$B$6:$B$138,B9&"*",'问卷正文 Questionnaire'!$K$6:$K$138,"R") -> 4 | G9: =COUNTIFS('问卷正文 Questionnaire'!$B$6:$B$138,B9&"*",'问卷正文 Questionnaire'!$K$6:$K$138,"R",'问卷正文 Questionnaire'!$H$6:$H$138,"否") -> 0
B10: P5 安全·包容与环境职场 | C10: =COUNTIF('问卷正文 Questionnaire'!$B$6:$B$138,B10&"*") -> 38 | D10: =IF(SUMIFS('问卷正文 Questionnaire'!$O$6:$O$138,'问卷正文 Questionnaire'!$B$6:$B$138,B10&"*")=0,"—",ROUND(SUMIFS('问卷正文 Questionnaire'!$P$6:$P$138,'问卷正文 Questionnaire'!$B$6:$B$138,B10&"*")/SUMIFS('问卷正文 Questionnaire'!$O$6:$O$138,'问卷正文 Questionnaire'!$B$6:$B$138,B10&"*")*100,1)) -> 0 | E10: =SUMIFS('问卷正文 Questionnaire'!$O$6:$O$138,'问卷正文 Questionnaire'!$B$6:$B$138,B10&"*") -> 40 | F10: =COUNTIFS('问卷正文 Questionnaire'!$B$6:$B$138,B10&"*",'问卷正文 Questionnaire'!$K$6:$K$138,"R") -> 12 | G10: =COUNTIFS('问卷正文 Questionnaire'!$B$6:$B$138,B10&"*",'问卷正文 Questionnaire'!$K$6:$K$138,"R",'问卷正文 Questionnaire'!$H$6:$H$138,"否") -> 0
B11: P6 拯救更多生命 · 道路安全 | C11: =COUNTIF('问卷正文 Questionnaire'!$B$6:$B$138,B11&"*") -> 3 | D11: =IF(SUMIFS('问卷正文 Questionnaire'!$O$6:$O$138,'问卷正文 Questionnaire'!$B$6:$B$138,B11&"*")=0,"—",ROUND(SUMIFS('问卷正文 Questionnaire'!$P$6:$P$138,'问卷正文 Questionnaire'!$B$6:$B$138,B11&"*")/SUMIFS('问卷正文 Questionnaire'!$O$6:$O$138,'问卷正文 Questionnaire'!$B$6:$B$138,B11&"*")*100,1)) -> 0 | E11: =SUMIFS('问卷正文 Questionnaire'!$O$6:$O$138,'问卷正文 Questionnaire'!$B$6:$B$138,B11&"*") -> 5 | F11: =COUNTIFS('问卷正文 Questionnaire'!$B$6:$B$138,B11&"*",'问卷正文 Questionnaire'!$K$6:$K$138,"R") -> 1 | G11: =COUNTIFS('问卷正文 Questionnaire'!$B$6:$B$138,B11&"*",'问卷正文 Questionnaire'!$K$6:$K$138,"R",'问卷正文 Questionnaire'!$H$6:$H$138,"否") -> 0
B12: 总计 TOTAL | C12: =COUNTA('问卷正文 Questionnaire'!$A$6:$A$138) -> 133 | D12: =IF(SUM('问卷正文 Questionnaire'!$O$6:$O$138)=0,"—",ROUND(SUM('问卷正文 Questionnaire'!$P$6:$P$138)/SUM('问卷正文 Questionnaire'!$O$6:$O$138)*100,1)) -> 0 | E12: =SUM('问卷正文 Questionnaire'!$O$6:$O$138) -> 173 | F12: =COUNTIF('问卷正文 Questionnaire'!$K$6:$K$138,"R") -> 28 | G12: =COUNTIFS('问卷正文 Questionnaire'!$K$6:$K$138,"R",'问卷正文 Questionnaire'!$H$6:$H$138,"否") -> 0
B14: =IF(G12>0,"⚠ 存在 "&G12&" 项最低要求(R)未达标 —— 未过最低门槛，须优先整改。 Below-minimum: not passed.","✓ 所有最低要求(R)均已满足。 All Requirements met.") -> ✓ 所有最低要求(R)均已满足。 All Requirements met.
B16: 数据校验 Data checks
B17: • 未作答 No answer | D17: =COUNTBLANK('问卷正文 Questionnaire'!$H$6:$H$138) -> 133
B18: • 答『是』但缺支持信息 Yes w/o support | D18: =SUMPRODUCT(('问卷正文 Questionnaire'!$H$6:$H$138="是")*('问卷正文 Questionnaire'!$I$6:$I$138="")) -> 0
B19: • 最低要求(R)未达标 Below-minimum | D19: =COUNTIFS('问卷正文 Questionnaire'!$K$6:$K$138,"R",'问卷正文 Questionnaire'!$H$6:$H$138,"否") -> 0

Sheet 权重表 Weights
A1: 编号 No. | B1: 支柱 Pillar | C1: 权重 Weight | D1: 强制 Type | E1: 题目 Question(CN)
A2: 1 | B2: P1 可持续管理框架与传导 | C2: 1 | D2: R | E2: 公司是否任命高管层的可持续发展负责人（涵盖社会/合规/环境），职责已成文并保持联系方式更新？
A3: 2 | B3: P1 可持续管理框架与传导 | C3: 1 | D3: 计分 | E3: 选择供应商时，是否将低碳与可持续要求（含 Autoliv 采购要求）作为准入与选择标准？
A4: 3 | B4: P1 可持续管理框架与传导 | C4: 3 | D4: R | E4: 是否已将 Autoliv 全部可持续采购要求逐条传导至上游（Tier-2），并验证 Tier-2 已采纳、要求其继续向 Tier-3 传导？
A5: 4 | B5: P1 可持续管理框架与传导 | C5: 1 | D5: 计分 | E5: 是否对上游供应商开展环保与减排培训？（培训记录即作为支持信息）
A6: 5 | B6: P1 可持续管理框架与传导 | C6: 1 | D6: E | E6: 是否能按 Autoliv 零件号将供应链追溯至 Tier-N（含原材料级），并全力配合 Autoliv 信息请求？
A7: 6 | B7: P1 可持续管理框架与传导 | C7: 1 | D7: 计分 | E7: 是否建立对上游供应商定期环境（及可持续）考核机制，并要求考核结果较差的供应商限期改善？
A8: 7 | B8: P1 可持续管理框架与传导 | C8: 1 | D8: R | E8: 是否承诺按 Autoliv 要求 100% 完整完成年度供应商可持续自评问卷（本问卷 / SupplierAssurance-NQC 平台）？
A9: 8 | B9: P1 可持续管理框架与传导 | C9: 3 | D9: R | E9: 是否接受并全力配合 Autoliv 及其授权第三方的现场审核，并对发现项制定与落实纠正措施（每 3 年或按风险提前）？
A10: 9 | B10: P2 气候中和 | C10: 1 | D10: 计分 | E10: 是否在工厂发展战略规划、发展理念等管理方针文件中，包含节能减排等相关内容？
A11: 10 | B11: P2 气候中和 | C11: 1 | D11: R | E11: 是否有（1）能耗数据统计和（2）碳排放计算和管理？
A12: 11 | B12: P2 气候中和 | C12: 1 | D12: R | E12: 是否知道碳减排的概念和知识，是否已经或正在制定碳减排的方案？
A13: 12 | B13: P2 气候中和 | C13: 1 | D13: R | E13: 是否有负责碳排放统计和管理人员？
... A134: 133 | B134: P6 拯救更多生命 · 道路安全 | C134: 1 | D134: E | E134: 重型货车（HGV）是否配备气囊、安全带与酒精锁，新购运输车辆是否按所在市场最高安全评级采购？
